<?xml version="1.0" encoding="UTF-8"?>
<testng-results ignored="0" total="1" passed="0" failed="0" skipped="1">
  <reporter-output>
  </reporter-output>
  <suite started-at="2020-02-27T22:46:15 IST" name="Default suite" finished-at="2020-02-27T22:46:30 IST" duration-ms="15792">
    <groups>
    </groups>
    <test started-at="2020-02-27T22:46:15 IST" name="Default test" finished-at="2020-02-27T22:46:30 IST" duration-ms="15792">
      <class name="test_Cases.Rename_Drop">
        <test-method is-config="true" signature="Openbrowser()[pri:0, instance:test_Cases.Rename_Drop@222114ba]" started-at="2020-02-27T22:46:15 IST" name="Openbrowser" finished-at="2020-02-27T22:46:29 IST" duration-ms="14831" status="PASS">
          <reporter-output>
          </reporter-output>
        </test-method> <!-- Openbrowser -->
        <test-method is-config="true" signature="login()[pri:0, instance:test_Cases.Rename_Drop@222114ba]" started-at="2020-02-27T22:46:29 IST" name="login" finished-at="2020-02-27T22:46:30 IST" duration-ms="793" status="FAIL">
          <exception class="java.lang.AssertionError">
            <message>
              <![CDATA[login not successfully expected [Welcome back!] but found []]]>
            </message>
            <full-stacktrace>
              <![CDATA[java.lang.AssertionError: login not successfully expected [Welcome back!] but found []
at org.testng.Assert.fail(Assert.java:97)
at org.testng.Assert.assertEqualsImpl(Assert.java:136)
at org.testng.Assert.assertEquals(Assert.java:118)
at org.testng.Assert.assertEquals(Assert.java:575)
at object_Repository.Base_Class.login(Base_Class.java:66)
at java.base/jdk.internal.reflect.NativeMethodAccessorImpl.invoke0(Native Method)
at java.base/jdk.internal.reflect.NativeMethodAccessorImpl.invoke(NativeMethodAccessorImpl.java:62)
at java.base/jdk.internal.reflect.DelegatingMethodAccessorImpl.invoke(DelegatingMethodAccessorImpl.java:43)
at java.base/java.lang.reflect.Method.invoke(Method.java:567)
at org.testng.internal.MethodInvocationHelper.invokeMethod(MethodInvocationHelper.java:133)
at org.testng.internal.MethodInvocationHelper.invokeMethodConsideringTimeout(MethodInvocationHelper.java:62)
at org.testng.internal.ConfigInvoker.invokeConfigurationMethod(ConfigInvoker.java:340)
at org.testng.internal.ConfigInvoker.invokeConfigurations(ConfigInvoker.java:294)
at org.testng.internal.TestMethodWorker.invokeBeforeClassMethods(TestMethodWorker.java:176)
at org.testng.internal.TestMethodWorker.run(TestMethodWorker.java:122)
at java.base/java.util.ArrayList.forEach(ArrayList.java:1507)
at org.testng.TestRunner.privateRun(TestRunner.java:770)
at org.testng.TestRunner.run(TestRunner.java:591)
at org.testng.SuiteRunner.runTest(SuiteRunner.java:402)
at org.testng.SuiteRunner.runSequentially(SuiteRunner.java:396)
at org.testng.SuiteRunner.privateRun(SuiteRunner.java:355)
at org.testng.SuiteRunner.run(SuiteRunner.java:304)
at org.testng.SuiteRunnerWorker.runSuite(SuiteRunnerWorker.java:53)
at org.testng.SuiteRunnerWorker.run(SuiteRunnerWorker.java:96)
at org.testng.TestNG.runSuitesSequentially(TestNG.java:1180)
at org.testng.TestNG.runSuitesLocally(TestNG.java:1102)
at org.testng.TestNG.runSuites(TestNG.java:1032)
at org.testng.TestNG.run(TestNG.java:1000)
at org.testng.remote.AbstractRemoteTestNG.run(AbstractRemoteTestNG.java:115)
at org.testng.remote.RemoteTestNG.initAndRun(RemoteTestNG.java:251)
at org.testng.remote.RemoteTestNG.main(RemoteTestNG.java:77)
]]>
            </full-stacktrace>
          </exception> <!-- java.lang.AssertionError -->
          <reporter-output>
          </reporter-output>
        </test-method> <!-- login -->
        <test-method signature="Rename_The_Drop()[pri:0, instance:test_Cases.Rename_Drop@222114ba]" started-at="2020-02-27T22:46:30 IST" name="Rename_The_Drop" finished-at="2020-02-27T22:46:30 IST" duration-ms="0" status="SKIP">
          <exception class="java.lang.AssertionError">
            <message>
              <![CDATA[login not successfully expected [Welcome back!] but found []]]>
            </message>
            <full-stacktrace>
              <![CDATA[java.lang.AssertionError: login not successfully expected [Welcome back!] but found []
at org.testng.Assert.fail(Assert.java:97)
at org.testng.Assert.assertEqualsImpl(Assert.java:136)
at org.testng.Assert.assertEquals(Assert.java:118)
at org.testng.Assert.assertEquals(Assert.java:575)
at object_Repository.Base_Class.login(Base_Class.java:66)
at java.base/jdk.internal.reflect.NativeMethodAccessorImpl.invoke0(Native Method)
at java.base/jdk.internal.reflect.NativeMethodAccessorImpl.invoke(NativeMethodAccessorImpl.java:62)
at java.base/jdk.internal.reflect.DelegatingMethodAccessorImpl.invoke(DelegatingMethodAccessorImpl.java:43)
at java.base/java.lang.reflect.Method.invoke(Method.java:567)
at org.testng.internal.MethodInvocationHelper.invokeMethod(MethodInvocationHelper.java:133)
at org.testng.internal.MethodInvocationHelper.invokeMethodConsideringTimeout(MethodInvocationHelper.java:62)
at org.testng.internal.ConfigInvoker.invokeConfigurationMethod(ConfigInvoker.java:340)
at org.testng.internal.ConfigInvoker.invokeConfigurations(ConfigInvoker.java:294)
at org.testng.internal.TestMethodWorker.invokeBeforeClassMethods(TestMethodWorker.java:176)
at org.testng.internal.TestMethodWorker.run(TestMethodWorker.java:122)
at java.base/java.util.ArrayList.forEach(ArrayList.java:1507)
at org.testng.TestRunner.privateRun(TestRunner.java:770)
at org.testng.TestRunner.run(TestRunner.java:591)
at org.testng.SuiteRunner.runTest(SuiteRunner.java:402)
at org.testng.SuiteRunner.runSequentially(SuiteRunner.java:396)
at org.testng.SuiteRunner.privateRun(SuiteRunner.java:355)
at org.testng.SuiteRunner.run(SuiteRunner.java:304)
at org.testng.SuiteRunnerWorker.runSuite(SuiteRunnerWorker.java:53)
at org.testng.SuiteRunnerWorker.run(SuiteRunnerWorker.java:96)
at org.testng.TestNG.runSuitesSequentially(TestNG.java:1180)
at org.testng.TestNG.runSuitesLocally(TestNG.java:1102)
at org.testng.TestNG.runSuites(TestNG.java:1032)
at org.testng.TestNG.run(TestNG.java:1000)
at org.testng.remote.AbstractRemoteTestNG.run(AbstractRemoteTestNG.java:115)
at org.testng.remote.RemoteTestNG.initAndRun(RemoteTestNG.java:251)
at org.testng.remote.RemoteTestNG.main(RemoteTestNG.java:77)
]]>
            </full-stacktrace>
          </exception> <!-- java.lang.AssertionError -->
          <reporter-output>
          </reporter-output>
        </test-method> <!-- Rename_The_Drop -->
        <test-method is-config="true" signature="logout()[pri:0, instance:test_Cases.Rename_Drop@222114ba]" started-at="2020-02-27T22:46:30 IST" name="logout" finished-at="1970-01-01T05:30:00 IST" duration-ms="-1582823790813" status="SKIP">
          <reporter-output>
          </reporter-output>
        </test-method> <!-- logout -->
        <test-method is-config="true" signature="closebrowser()[pri:0, instance:test_Cases.Rename_Drop@222114ba]" started-at="2020-02-27T22:46:30 IST" name="closebrowser" finished-at="2020-02-27T22:46:30 IST" duration-ms="80" status="PASS">
          <reporter-output>
          </reporter-output>
        </test-method> <!-- closebrowser -->
      </class> <!-- test_Cases.Rename_Drop -->
    </test> <!-- Default test -->
  </suite> <!-- Default suite -->
</testng-results>
